LSTM:

loss:ERROR:tensorflow:Exception in QueueRunner: Enqueue operation was cancelled
	 [[Node: PTBProducer/input_producer/input_producer_EnqueueMany = QueueEnqueueManyV2[Tcomponents=[DT_INT32], timeout_ms=-1, _device="/job:localhost/replica:0/task:0/cpu:0"](PTBProducer/input_producer, PTBProducer/input_producer/range)]] 
[7.4175243, None]

Exception in thread Thread-4:
Traceback (most recent call last):
  File "/usr/lib/python3.5/threading.py", line 914, in _bootstrap_inner
    self.run()
  File "/usr/lib/python3.5/threading.py", line 862, in run
    self._target(*self._args, **self._kwargs)
  File "/home/gimli2/venvs/mi-mvi/lib/python3.5/site-packages/tensorflow/python/training/queue_runner_impl.py", line 238, in _run
    enqueue_callable()
  File "/home/gimli2/venvs/mi-mvi/lib/python3.5/site-packages/tensorflow/python/client/session.py", line 1235, in _single_operation_run
    target_list_as_strings, status, None)
  File "/usr/lib/python3.5/contextlib.py", line 66, in __exit__
    next(self.gen)
  File "/home/gimli2/venvs/mi-mvi/lib/python3.5/site-packages/tensorflow/python/framework/errors_impl.py", line 466, in raise_exception_on_not_ok_status
    pywrap_tensorflow.TF_GetCode(status))
tensorflow.python.framework.errors_impl.CancelledError: Enqueue operation was cancelled
	 [[Node: PTBProducer/input_producer/input_producer_EnqueueMany = QueueEnqueueManyV2[Tcomponents=[DT_INT32], timeout_ms=-1, _device="/job:localhost/replica:0/task:0/cpu:0"](PTBProducer/input_producer, PTBProducer/input_producer/range)]]


VANILLA
step: 999
loss: [33.62912, None]
ERROR:tensorflow:Exception in QueueRunner: Enqueue operation was cancelled
	 [[Node: PTBProducer/input_producer/input_producer_EnqueueMany = QueueEnqueueManyV2[Tcomponents=[DT_INT32], timeout_ms=-1, _device="/job:localhost/replica:0/task:0/cpu:0"](PTBProducer/input_producer, PTBProducer/input_producer/range)]]
Exception in thread Thread-5:
Traceback (most recent call last):
  File "/usr/lib/python3.5/threading.py", line 914, in _bootstrap_inner
    self.run()
  File "/usr/lib/python3.5/threading.py", line 862, in run
    self._target(*self._args, **self._kwargs)
  File "/home/gimli2/venvs/mi-mvi/lib/python3.5/site-packages/tensorflow/python/training/queue_runner_impl.py", line 238, in _run
    enqueue_callable()
  File "/home/gimli2/venvs/mi-mvi/lib/python3.5/site-packages/tensorflow/python/client/session.py", line 1235, in _single_operation_run
    target_list_as_strings, status, None)
  File "/usr/lib/python3.5/contextlib.py", line 66, in __exit__
    next(self.gen)
  File "/home/gimli2/venvs/mi-mvi/lib/python3.5/site-packages/tensorflow/python/framework/errors_impl.py", line 466, in raise_exception_on_not_ok_status
    pywrap_tensorflow.TF_GetCode(status))
tensorflow.python.framework.errors_impl.CancelledError: Enqueue operation was cancelled
	 [[Node: PTBProducer/input_producer/input_producer_EnqueueMany = QueueEnqueueManyV2[Tcomponents=[DT_INT32], timeout_ms=-1, _device="/job:localhost/replica:0/task:0/cpu:0"](PTBProducer/input_producer, PTBProducer/input_producer/range)]]

